Workbook

Sheet Resumo
B4: Nome: | C4: teste
B5: Agência/Conta: | C5: 2846/146465-5
B6: Período:
B8: SALDOS
B9: Saldo Inicial: | C9: 1,00
B10: Saldo Final: | C10: 1
B12: TOTALIZADORES
B13: Total Tarifas/Custas: | C13: -358.6
B14: Total Créditos: | C14: 121630.27
B15: Total Débitos: | C15: -164066.69
B16: Total Aplicações: | C16: 0
B18: APLICAÇÕES
B20: CDB
B21: Saldo Inicial: | C21: 0
B22: Saldo Final: | C22: 0
B24: INVEST FACIL
B25: Saldo Inicial: | C25: 0
B26: Saldo Final: | C26: 0
B28: Indefinido
B29: Saldo Inicial: | C29: 0
B30: Saldo Final: | C30: 0
B32: Indefinido2
B33: Saldo Inicial: | C33: 0
B34: Saldo Final: | C34: 0

Sheet Tarifas
B2: Bradesco
B5: Nome: | C5: teste | D5: Agência/Conta:
B6: Data: | D6: 2846/146465-5
B9: APURAÇÃO TARIFAS BANCÁRIAS
B12: Data | C12: Lançamento | D12: Debito (R$)
B13: 02/01/2026 | C13: TAR CC REAL TIME PAGFOR | D13: -1.95
B14: 05/01/2026 | C14: TARIFA REGISTRO COBRANCA NA BAIXA POR PAGAMENTO 00000001 | D14: -1.66
B15: 06/01/2026 | C15: TARIFA REGISTRO COBRANCA NA BAIXA POR COMPENSACAO00000001 | D15: -1.66
B16: 06/01/2026 | C16: TARIFA AUTORIZ COBRANCA EXTRATO DE COBRANCA 00000001 | D16: -2.28
B17: 06/01/2026 | C17: TARIFA LCTO CRED CONTA | D17: -13.16
B18: 07/01/2026 | C18: TARIFA AUTORIZ COBRANCA EXTRATO DE COBRANCA 00000001 | D18: -2.28
B19: 08/01/2026 | C19: TARIFA REGISTRO COBRANCA NA BAIXA POR COMPENSACAO00000001 | D19: -1.66
B20: 08/01/2026 | C20: TARIFA REGISTRO COBRANCA NA BAIXA POR PAGAMENTO 00000002 | D20: -3.32
B21: 09/01/2026 | C21: TARIFA REGISTRO COBRANCA NA BAIXA POR COMPENSACAO00000001 | D21: -1.66
B22: 09/01/2026 | C22: TARIFA AUTORIZ COBRANCA EXTRATO DE COBRANCA 00000001 | D22: -2.28
B23: 09/01/2026 | C23: TAR CC REAL TIME PAGFOR | D23: -1.95
B24: 09/01/2026 | C24: TAR SERV TED STR PAGFOR | D24: -10.96
... B46: 30/01/2026 | C46: TAR SERV TED STR PAGFOR | D46: -21.92
B47: TOTAL | D47: =SUM(D13:D46)

Sheet Aplicacoes
B2: Bradesco
B5: Nome: | C5: teste | D5: Agência/Conta: | E5: 2846/146465-5
B6: Período:
B9: APLICAÇÕES
B12: GRUPO: CDB
B13: Data | C13: Lançamento | D13: Aplicação (R$) | E13: Resgate (R$)
B14: 02/01/2026 | C14: RESG/VENCTO CDB | E14: 2088.09
B15: 05/01/2026 | C15: RESG/VENCTO CDB | E15: 244.69
B16: 06/01/2026 | C16: RESG/VENCTO CDB | E16: 8841.48
B17: 06/01/2026 | C17: RESG/VENCTO CDB | E17: 10416.56
B18: 07/01/2026 | C18: RESG/VENCTO CDB | E18: 100
B19: 29/01/2026 | C19: RESG/VENCTO CDB | E19: 19987.63
B20: 30/01/2026 | C20: RESG/VENCTO CDB | E20: 1116.57
B21: TOTAL | D21: =SUM(D14:D20) | E21: =SUM(E14:E20)
D22: Saldo Inicial: | E22: =Resumo!C21
D23: Saldo Final: | E23: =Resumo!C22
D24: Rendimento: | E24: =Resumo!C22-(Resumo!C21+(-D21)-E21)
B26: GRUPO: INVEST FACIL
B27: Data | C27: Lançamento | D27: Aplicação (R$) | E27: Resgate (R$)
B28: 12/01/2026 | C28: RENTAB.INVEST FACILCRED* | E28: 0.02
B29: 14/01/2026 | C29: RENTAB.INVEST FACILCRED* | E29: 0.01
B30: 15/01/2026 | C30: RENTAB.INVEST FACILCRED* | E30: 0.31
B31: 15/01/2026 | C31: RENTAB.INVEST FACILCRED* | E31: 0.03
B32: 15/01/2026 | C32: RENTAB.INVEST FACILCRED* | E32: 0.03
B33: 16/01/2026 | C33: RENTAB.INVEST FACILCRED* | E33: 0.08
B34: 19/01/2026 | C34: RENTAB.INVEST FACILCRED* | E34: 0.46
B35: 21/01/2026 | C35: RENTAB.INVEST FACILCRED* | E35: 0.34
B36: 22/01/2026 | C36: RENTAB.INVEST FACILCRED* | E36: 0.02
B37: 23/01/2026 | C37: RENTAB.INVEST FACILCRED* | E37: 0.14
B38: 26/01/2026 | C38: RENTAB.INVEST FACILCRED* | E38: 0.06
B39: 27/01/2026 | C39: RENTAB.INVEST FACILCRED* | E39: 0.05
... B42: 29/01/2026 | C42: RENTAB.INVEST FACILCRED* | E42: 1.55
B43: TOTAL | D43: =SUM(D28:D42) | E43: =SUM(E28:E42)
D44: Saldo Inicial: | E44: =Resumo!C25
D45: Saldo Final: | E45: =Resumo!C26
D46: Rendimento: | E46: =Resumo!C26-(Resumo!C25+(-D43)-E43)
B48: ="GRUPO: "&Resumo!B28
B49: Data | C49: Lançamento | D49: Aplicação (R$) | E49: Resgate (R$)
B50: Sem registros
B52: TOTAL | D52: =SUM(D50:D51) | E52: =SUM(E50:E51)
...

Sheet Geral
B2: Bradesco
B5: Nome: | C5: teste | D5: Agência/Conta:
B6: Data: | D6: 2846/146465-5
B9: GERAL
B10: CRÉDITOS
B12: Data | C12: Lançamento | D12: Credito (R$)
B13: 05/01/2026 | C13: LIQUIDACAO DE COBRANCA VALOR DISPONIVEL | D13: 5588.84
B14: 06/01/2026 | C14: LIQUIDACAO DE COBRANCA VALOR DISPONIVEL | D14: 3917.58
B15: 08/01/2026 | C15: LIQUIDACAO DE COBRANCA VALOR DISPONIVEL | D15: 15465.69
B16: 09/01/2026 | C16: LIQUIDACAO DE COBRANCA VALOR DISPONIVEL | D16: 5370.3
B17: 13/01/2026 | C17: LIQUIDACAO DE COBRANCA VALOR DISPONIVEL | D17: 72523.03
B18: 20/01/2026 | C18: LIQUIDACAO DE COBRANCA VALOR DISPONIVEL | D18: 5370.3
B19: 22/01/2026 | C19: LIQUIDACAO DE COBRANCA VALOR DISPONIVEL | D19: 3995.93
B20: 29/01/2026 | C20: LIQUIDACAO DE COBRANCA VALOR DISPONIVEL | D20: 5477.7
B21: 30/01/2026 | C21: LIQUIDACAO DE COBRANCA VALOR DISPONIVEL | D21: 3917.58
B22: TOTAL | D22: =SUM(D13:D21)
B23: DÉBITOS
B25: Data | C25: Lançamento | D25: Debito (R$)
B26: 02/01/2026 | C26: PAGFOR C/C R TIME SD L | D26: -1581.14
B27: 02/01/2026 | C27: PFOR TIT OUTROS BANCOS | D27: -505
B28: 05/01/2026 | C28: PFOR TIT OUTROS BANCOS | D28: -5831.87
B29: 06/01/2026 | C29: PAGAMENTO FUNCIONARIOS | D29: -18341.84
B30: 06/01/2026 | C30: PFOR TIT OUTROS BANCOS | D30: -4816.67
B31: 09/01/2026 | C31: PAGFOR C/C R TIME SD L | D31: -673
B32: 09/01/2026 | C32: PFOR TIT OUTROS BANCOS | D32: -1044
B33: 09/01/2026 | C33: PAGTO ELETRONICO TRIBUTO PGIT - COD.BARRAS-PMSP5701 | D33: -28.13
B34: 09/01/2026 | C34: PAGFOR TED STR SD DISP | D34: -1130.68
B35: 09/01/2026 | C35: PFOR TIT BRADESCO SD L | D35: -1094.4
B36: 12/01/2026 | C36: TV POR ASSINATURA CLARO SA-RESIDENCIAL-9180322 | D36: -206.14
B37: 12/01/2026 | C37: PFOR TIT OUTROS BANCOS | D37: -202.52
... B67: 30/01/2026 | C67: PAGFOR TED STR SD DISP | D67: -4835.37
B68: TOTAL | D68: =SUM(D26:D67)
B71: Saldo Inicial: | C71: 1,00
B72: Saldo Final: | C72: 1
